<?xml version="1.0" ?>
<!-- =================================================================================== -->
<!-- |    This document was autogenerated by xacro from ur3_sim.urdf.xacro             | -->
<!-- |    EDITING THIS FILE BY HAND IS NOT RECOMMENDED                                 | -->
<!-- =================================================================================== -->
<robot name="ur3">
  <gazebo>
    <plugin filename="libgazebo_ros_control.so" name="ros_control">
      <!--robotNamespace>/</robotNamespace-->
      <!--robotSimType>gazebo_ros_control/DefaultRobotHWSim</robotSimType-->
    </plugin>
    <!--
    <plugin name="gazebo_ros_power_monitor_controller" filename="libgazebo_ros_power_monitor.so">
      <alwaysOn>true</alwaysOn>
      <updateRate>1.0</updateRate>
      <timeout>5</timeout>
      <powerStateTopic>power_state</powerStateTopic>
      <powerStateRate>10.0</powerStateRate>
      <fullChargeCapacity>87.78</fullChargeCapacity>     
      <dischargeRate>-474</dischargeRate>
      <chargeRate>525</chargeRate>
      <dischargeVoltage>15.52</dischargeVoltage>
      <chargeVoltage>16.41</chargeVoltage>
    </plugin>
-->
  </gazebo>
  <!--
  Author: Felix Messmer
-->
  <!-- measured from model -->
  <link name="base_link">
    <visual>
      <geometry>
        <mesh filename="package://ur_description/meshes/ur3/visual/base.dae"/>
      </geometry>
      <material name="LightGrey">
        <color rgba="0.7 0.7 0.7 1.0"/>
      </material>
    </visual>
    <collision>
      <geometry>
        <mesh filename="package://ur_description/meshes/ur3/collision/base.stl"/>
      </geometry>
    </collision>
    <inertial>
      <mass value="2.0"/>
      <origin rpy="0 0 0" xyz="0.0 0.0 0.0"/>
      <inertia ixx="0.0030531654454" ixy="0.0" ixz="0.0" iyy="0.0030531654454" iyz="0.0" izz="0.005625"/>
    </inertial>
  </link>
  <joint name="shoulder_pan_joint" type="revolute">
    <parent link="base_link"/>
    <child link="shoulder_link"/>
    <origin rpy="0.0 0.0 0.0" xyz="0.0 0.0 0.1519"/>
    <axis xyz="0 0 1"/>
    <limit effort="330.0" lower="-3.141592653589793" upper="3.141592653589793" velocity="2.16"/>
    <dynamics damping="0.0" friction="0.0"/>
  </joint>
  <link name="shoulder_link">
    <visual>
      <geometry>
        <mesh filename="package://ur_description/meshes/ur3/visual/shoulder.dae"/>
      </geometry>
      <material name="LightGrey">
        <color rgba="0.7 0.7 0.7 1.0"/>
      </material>
    </visual>
    <collision>
      <geometry>
        <mesh filename="package://ur_description/meshes/ur3/collision/shoulder.stl"/>
      </geometry>
    </collision>
    <inertial>
      <mass value="2.0"/>
      <origin rpy="0 0 0" xyz="0.0 0.0 0.0"/>
      <inertia ixx="0.008093163429399999" ixy="0.0" ixz="0.0" iyy="0.008093163429399999" iyz="0.0" izz="0.005625"/>
    </inertial>
  </link>
  <joint name="shoulder_lift_joint" type="revolute">
    <parent link="shoulder_link"/>
    <child link="upper_arm_link"/>
    <origin rpy="0.0 1.5707963267948966 0.0" xyz="0.0 0.1198 0.0"/>
    <axis xyz="0 1 0"/>
    <limit effort="330.0" lower="-3.141592653589793" upper="3.141592653589793" velocity="2.16"/>
    <dynamics damping="0.0" friction="0.0"/>
  </joint>
  <link name="upper_arm_link">
    <visual>
      <geometry>
        <mesh filename="package://ur_description/meshes/ur3/visual/upperarm.dae"/>
      </geometry>
      <material name="LightGrey">
        <color rgba="0.7 0.7 0.7 1.0"/>
      </material>
    </visual>
    <collision>
      <geometry>
        <mesh filename="package://ur_description/meshes/ur3/collision/upperarm.stl"/>
      </geometry>
    </collision>
    <inertial>
      <mass value="3.42"/>
      <origin rpy="0 0 0" xyz="0.0 0.0 0.121825"/>
      <inertia ixx="0.021728483221103233" ixy="0.0" ixz="0.0" iyy="0.021728483221103233" iyz="0.0" izz="0.00961875"/>
    </inertial>
  </link>
  <joint name="elbow_joint" type="revolute">
    <parent link="upper_arm_link"/>
    <child link="forearm_link"/>
    <origin rpy="0.0 0.0 0.0" xyz="0.0 -0.0925 0.24365"/>
    <axis xyz="0 1 0"/>
    <limit effort="150.0" lower="-3.141592653589793" upper="3.141592653589793" velocity="3.15"/>
    <dynamics damping="0.0" friction="0.0"/>
  </joint>
  <link name="forearm_link">
    <visual>
      <geometry>
        <mesh filename="package://ur_description/meshes/ur3/visual/forearm.dae"/>
      </geometry>
      <material name="LightGrey">
        <color rgba="0.7 0.7 0.7 1.0"/>
      </material>
    </visual>
    <collision>
      <geometry>
        <mesh filename="package://ur_description/meshes/ur3/collision/forearm.stl"/>
      </geometry>
    </collision>
    <inertial>
      <mass value="1.26"/>
      <origin rpy="0 0 0" xyz="0.0 0.0 0.106625"/>
      <inertia ixx="0.006546806443776375" ixy="0.0" ixz="0.0" iyy="0.006546806443776375" iyz="0.0" izz="0.00354375"/>
    </inertial>
  </link>
  <joint name="wrist_1_joint" type="revolute">
    <parent link="forearm_link"/>
    <child link="wrist_1_link"/>
    <origin rpy="0.0 1.5707963267948966 0.0" xyz="0.0 0.0 0.21325"/>
    <axis xyz="0 1 0"/>
    <limit effort="54.0" lower="-3.141592653589793" upper="3.141592653589793" velocity="3.2"/>
    <dynamics damping="0.0" friction="0.0"/>
  </joint>
  <link name="wrist_1_link">
    <visual>
      <geometry>
        <mesh filename="package://ur_description/meshes/ur3/visual/wrist1.dae"/>
      </geometry>
      <material name="LightGrey">
        <color rgba="0.7 0.7 0.7 1.0"/>
      </material>
    </visual>
    <collision>
      <geometry>
        <mesh filename="package://ur_description/meshes/ur3/collision/wrist1.stl"/>
      </geometry>
    </collision>
    <inertial>
      <mass value="0.8"/>
      <origin rpy="0 0 0" xyz="0.0 0.08505 0.0"/>
      <inertia ixx="0.002084999166" ixy="0.0" ixz="0.0" iyy="0.002084999166" iyz="0.0" izz="0.00225"/>
    </inertial>
  </link>
  <joint name="wrist_2_joint" type="revolute">
    <parent link="wrist_1_link"/>
    <child link="wrist_2_link"/>
    <origin rpy="0.0 0.0 0.0" xyz="0.0 0.08505 0.0"/>
    <axis xyz="0 0 1"/>
    <limit effort="54.0" lower="-3.141592653589793" upper="3.141592653589793" velocity="3.2"/>
    <dynamics damping="0.0" friction="0.0"/>
  </joint>
  <link name="wrist_2_link">
    <visual>
      <geometry>
        <mesh filename="package://ur_description/meshes/ur3/visual/wrist2.dae"/>
      </geometry>
      <material name="LightGrey">
        <color rgba="0.7 0.7 0.7 1.0"/>
      </material>
    </visual>
    <collision>
      <geometry>
        <mesh filename="package://ur_description/meshes/ur3/collision/wrist2.stl"/>
      </geometry>
    </collision>
    <inertial>
      <mass value="0.8"/>
      <origin rpy="0 0 0" xyz="0.0 0.0 0.08535"/>
      <inertia ixx="0.002084999166" ixy="0.0" ixz="0.0" iyy="0.002084999166" iyz="0.0" izz="0.00225"/>
    </inertial>
  </link>
  <joint name="wrist_3_joint" type="revolute">
    <parent link="wrist_2_link"/>
    <child link="wrist_3_link"/>
    <origin rpy="0.0 0.0 0.0" xyz="0.0 0.0 0.08535"/>
    <axis xyz="0 1 0"/>
    <limit effort="54.0" lower="-3.141592653589793" upper="3.141592653589793" velocity="3.2"/>
    <dynamics damping="0.0" friction="0.0"/>
  </joint>
  <link name="wrist_3_link">
    <visual>
      <geometry>
        <mesh filename="package://ur_description/meshes/ur3/visual/wrist3.dae"/>
      </geometry>
      <material name="LightGrey">
        <color rgba="0.7 0.7 0.7 1.0"/>
      </material>
    </visual>
    <collision>
      <geometry>
        <mesh filename="package://ur_description/meshes/ur3/collision/wrist3.stl"/>
      </geometry>
    </collision>
    <inertial>
      <mass value="0.35"/>
      <origin rpy="1.5707963267948966 0 0" xyz="0.0 0.0619 0.0"/>
      <inertia ixx="0.00013626661215999998" ixy="0.0" ixz="0.0" iyy="0.00013626661215999998" iyz="0.0" izz="0.0001792"/>
    </inertial>
  </link>
  <joint name="ee_fixed_joint" type="fixed">
    <parent link="wrist_3_link"/>
    <child link="ee_link"/>
    <origin rpy="0.0 0.0 1.5707963267948966" xyz="0.0 0.0819 0.0"/>
  </joint>
  <link name="ee_link">
    <collision>
      <geometry>
        <box size="0.01 0.01 0.01"/>
      </geometry>
      <origin rpy="0 0 0" xyz="-0.01 0 0"/>
    </collision>
  </link>
  <transmission name="shoulder_pan_trans">
    <type>transmission_interface/SimpleTransmission</type>
    <joint name="shoulder_pan_joint">
      <hardwareInterface>hardware_interface/PositionJointInterface</hardwareInterface>
    </joint>
    <actuator name="shoulder_pan_motor">
      <mechanicalReduction>1</mechanicalReduction>
    </actuator>
  </transmission>
  <transmission name="shoulder_lift_trans">
    <type>transmission_interface/SimpleTransmission</type>
    <joint name="shoulder_lift_joint">
      <hardwareInterface>hardware_interface/PositionJointInterface</hardwareInterface>
    </joint>
    <actuator name="shoulder_lift_motor">
      <mechanicalReduction>1</mechanicalReduction>
    </actuator>
  </transmission>
  <transmission name="elbow_trans">
    <type>transmission_interface/SimpleTransmission</type>
    <joint name="elbow_joint">
      <hardwareInterface>hardware_interface/PositionJointInterface</hardwareInterface>
    </joint>
    <actuator name="elbow_motor">
      <mechanicalReduction>1</mechanicalReduction>
    </actuator>
  </transmission>
  <transmission name="wrist_1_trans">
    <type>transmission_interface/SimpleTransmission</type>
    <joint name="wrist_1_joint">
      <hardwareInterface>hardware_interface/PositionJointInterface</hardwareInterface>
    </joint>
    <actuator name="wrist_1_motor">
      <mechanicalReduction>1</mechanicalReduction>
    </actuator>
  </transmission>
  <transmission name="wrist_2_trans">
    <type>transmission_interface/SimpleTransmission</type>
    <joint name="wrist_2_joint">
      <hardwareInterface>hardware_interface/PositionJointInterface</hardwareInterface>
    </joint>
    <actuator name="wrist_2_motor">
      <mechanicalReduction>1</mechanicalReduction>
    </actuator>
  </transmission>
  <transmission name="wrist_3_trans">
    <type>transmission_interface/SimpleTransmission</type>
    <joint name="wrist_3_joint">
      <hardwareInterface>hardware_interface/PositionJointInterface</hardwareInterface>
    </joint>
    <actuator name="wrist_3_motor">
      <mechanicalReduction>1</mechanicalReduction>
    </actuator>
  </transmission>
  <gazebo reference="shoulder_link">
    <selfCollide>true</selfCollide>
  </gazebo>
  <gazebo reference="upper_arm_link">
    <selfCollide>true</selfCollide>
  </gazebo>
  <gazebo reference="forearm_link">
    <selfCollide>true</selfCollide>
  </gazebo>
  <gazebo reference="wrist_1_link">
    <selfCollide>true</selfCollide>
  </gazebo>
  <gazebo reference="wrist_3_link">
    <selfCollide>true</selfCollide>
  </gazebo>
  <gazebo reference="wrist_2_link">
    <selfCollide>true</selfCollide>
  </gazebo>
  <gazebo reference="ee_link">
    <selfCollide>true</selfCollide>
  </gazebo>
  <!-- ROS base_link to UR 'Base' Coordinates transform -->
  <link name="base"/>
  <joint name="base_link-base_fixed_joint" type="fixed">
    <!-- NOTE: this rotation is only needed as long as base_link itself is
                 not corrected wrt the real robot (ie: rotated over 180
                 degrees)
      -->
    <origin rpy="0 0 -3.141592653589793" xyz="0 0 0"/>
    <parent link="base_link"/>
    <child link="base"/>
  </joint>
  <!-- Frame coincident with all-zeros TCP on UR controller -->
  <link name="tool0"/>
  <joint name="wrist_3_link-tool0_fixed_joint" type="fixed">
    <origin rpy="-1.5707963267948966 0 0" xyz="0 0.0819 0"/>
    <parent link="wrist_3_link"/>
    <child link="tool0"/>
  </joint>
  <link name="world"/>
  <joint name="world_joint" type="fixed">
    <parent link="world"/>
    <child link="base_link"/>
    <origin rpy="0.0 0.0 0.0" xyz="0.0 0.0 0.0"/>
  </joint>
  <link name="tool_gripper"/>
  <joint name="tool_gripper_joint" type="fixed">
    <parent link="tool0"/>
    <child link="tool_gripper"/>
    <origin rpy="0.0 0.0 0.0" xyz="0.0 0.0 0.12084"/>
  </joint>
  <link name="cela_white">
    <visual>
      <geometry>
        <mesh filename="package://ur3_sim_description/meshes/cell/ERC2022_cela_white.dae" scale="0.001 0.001 0.001"/>
      </geometry>
    </visual>
    <collision>
      <geometry>
        <mesh filename="package://ur3_sim_description/meshes/cell/ERC2022_cela_white.dae" scale="0.001 0.001 0.001"/>
      </geometry>
    </collision>
    <inertial>
      <mass value="10"/>
      <inertia ixx="1.0" ixy="0.0" ixz="0.0" iyy="1.0" iyz="0.0" izz="1.0"/>
    </inertial>
  </link>
  <joint name="cela_white_joint" type="fixed">
    <parent link="world"/>
    <child link="cela_white"/>
    <origin rpy="0.0 0 -1.57079632679" xyz="-0.04 0.0 -0.14"/>
  </joint>
  <gazebo reference="cela_white">
    <material>Gazebo/White</material>
  </gazebo>
  <link name="cela_black">
    <visual>
      <geometry>
        <mesh filename="package://ur3_sim_description/meshes/cell/ERC2022_cela_black.dae" scale="0.001 0.001 0.001"/>
      </geometry>
    </visual>
    <collision>
      <geometry>
        <mesh filename="package://ur3_sim_description/meshes/cell/ERC2022_cela_black.dae" scale="0.001 0.001 0.001"/>
      </geometry>
    </collision>
    <inertial>
      <mass value="10"/>
      <inertia ixx="1.0" ixy="0.0" ixz="0.0" iyy="1.0" iyz="0.0" izz="1.0"/>
    </inertial>
  </link>
  <joint name="cela_black_joint" type="fixed">
    <parent link="world"/>
    <child link="cela_black"/>
    <origin rpy="0.0 0 -1.57079632679" xyz="-0.04 0.0 -0.14"/>
  </joint>
  <gazebo reference="cela_black">
    <material>Gazebo/Black</material>
  </gazebo>
  <link name="box_bottom">
    <visual>
      <geometry>
        <mesh filename="package://ur3_sim_description/meshes/box/ERC2022_box_bottom.dae" scale="0.001 0.001 0.001"/>
      </geometry>
    </visual>
    <collision>
      <geometry>
        <mesh filename="package://ur3_sim_description/meshes/box/ERC2022_box_bottom.dae" scale="0.001 0.001 0.001"/>
      </geometry>
    </collision>
    <inertial>
      <mass value="10"/>
      <inertia ixx="1.0" ixy="0.0" ixz="0.0" iyy="1.0" iyz="0.0" izz="1.0"/>
    </inertial>
  </link>
  <joint name="box_bottom_joint" type="fixed">
    <parent link="base_link"/>
    <child link="box_bottom"/>
    <origin rpy="0.0 0.0 -1.8849555922" xyz="0.3816 -0.29 0.17"/>
  </joint>
  <link name="box_top">
    <visual>
      <geometry>
        <mesh filename="package://ur3_sim_description/meshes/box/ERC2022_box_top.dae" scale="0.001 0.001 0.001"/>
      </geometry>
    </visual>
    <collision>
      <geometry>
        <mesh filename="package://ur3_sim_description/meshes/box/ERC2022_box_top.dae" scale="0.001 0.001 0.001"/>
      </geometry>
    </collision>
    <inertial>
      <mass value="10"/>
      <inertia ixx="1.0" ixy="0.0" ixz="0.0" iyy="1.0" iyz="0.0" izz="1.0"/>
    </inertial>
  </link>
  <joint name="box_top_joint" type="fixed">
    <parent link="base_link"/>
    <child link="box_top"/>
    <origin rpy="0.0 0.0 -1.8849555922" xyz="0.3816 -0.29 0.17"/>
  </joint>
  <link name="imu">
    <visual>
      <origin rpy="1.57075 1.57075 -3.1415" xyz="0 -0.025 0"/>
      <geometry>
        <mesh filename="package://ur3_sim_description/meshes/imu/ERC2022_IMU.dae" scale="0.001 0.001 0.001"/>
      </geometry>
    </visual>
    <collision>
      <origin rpy="1.57075 1.57075 -3.1415" xyz="0 -0.025 0"/>
      <geometry>
        <mesh filename="package://ur3_sim_description/meshes/imu/ERC2022_IMU.dae" scale="0.001 0.001 0.001"/>
      </geometry>
    </collision>
    <inertial>
      <mass value="10"/>
      <inertia ixx="1.0" ixy="0.0" ixz="0.0" iyy="1.0" iyz="0.0" izz="1.0"/>
    </inertial>
  </link>
  <joint name="imu_joint" type="fixed">
    <parent link="base_link"/>
    <child link="imu"/>
    <origin rpy="1.57075 0 0" xyz="0.19 0.26 -0.115"/>
  </joint>
  <link name="imu_panel"/>
  <joint name="imu_panel_joint" type="fixed">
    <parent link="imu"/>
    <child link="imu_panel"/>
    <origin rpy="0 1.57075 0" xyz="0 0 0"/>
  </joint>
  <link name="button1">
    <visual>
      <geometry>
        <mesh filename="package://ur3_sim_description/meshes/button/ERC2022_button_ID1.dae" scale="0.001 0.001 0.001"/>
      </geometry>
    </visual>
    <collision>
      <geometry>
        <mesh filename="package://ur3_sim_description/meshes/button/ERC2022_button_ID1.dae" scale="0.001 0.001 0.001"/>
      </geometry>
    </collision>
    <inertial>
      <mass value="10"/>
      <inertia ixx="1.0" ixy="0.0" ixz="0.0" iyy="1.0" iyz="0.0" izz="1.0"/>
    </inertial>
  </link>
  <joint name="button1_joint" type="fixed">
    <parent link="base_link"/>
    <child link="button1"/>
    <origin rpy="1.5707 0.0 -1.5707" xyz="0.477 0.06 0.35"/>
  </joint>
  <link name="button2">
    <visual>
      <geometry>
        <mesh filename="package://ur3_sim_description/meshes/button/ERC2022_button_ID2.dae" scale="0.001 0.001 0.001"/>
      </geometry>
    </visual>
    <collision>
      <geometry>
        <mesh filename="package://ur3_sim_description/meshes/button/ERC2022_button_ID2.dae" scale="0.001 0.001 0.001"/>
      </geometry>
    </collision>
    <inertial>
      <mass value="10"/>
      <inertia ixx="1.0" ixy="0.0" ixz="0.0" iyy="1.0" iyz="0.0" izz="1.0"/>
    </inertial>
  </link>
  <joint name="button2_joint" type="fixed">
    <parent link="base_link"/>
    <child link="button2"/>
    <origin rpy="1.5707 0.0 -1.5707" xyz="0.477 -0.06 0.35"/>
  </joint>
  <link name="button3">
    <visual>
      <geometry>
        <mesh filename="package://ur3_sim_description/meshes/button/ERC2022_button_ID3.dae" scale="0.001 0.001 0.001"/>
      </geometry>
    </visual>
    <collision>
      <geometry>
        <mesh filename="package://ur3_sim_description/meshes/button/ERC2022_button_ID3.dae" scale="0.001 0.001 0.001"/>
      </geometry>
    </collision>
    <inertial>
      <mass value="10"/>
      <inertia ixx="1.0" ixy="0.0" ixz="0.0" iyy="1.0" iyz="0.0" izz="1.0"/>
    </inertial>
  </link>
  <joint name="button3_joint" type="fixed">
    <parent link="base_link"/>
    <child link="button3"/>
    <origin rpy="1.5707 0.0 -1.5707" xyz="0.477 0.06 0.17"/>
  </joint>
  <link name="button4">
    <visual>
      <geometry>
        <mesh filename="package://ur3_sim_description/meshes/button/ERC2022_button_ID4.dae" scale="0.001 0.001 0.001"/>
      </geometry>
    </visual>
    <collision>
      <geometry>
        <mesh filename="package://ur3_sim_description/meshes/button/ERC2022_button_ID4.dae" scale="0.001 0.001 0.001"/>
      </geometry>
    </collision>
    <inertial>
      <mass value="10"/>
      <inertia ixx="1.0" ixy="0.0" ixz="0.0" iyy="1.0" iyz="0.0" izz="1.0"/>
    </inertial>
  </link>
  <joint name="button4_joint" type="fixed">
    <parent link="base_link"/>
    <child link="button4"/>
    <origin rpy="1.5707 0.0 -1.5707" xyz="0.477 -0.06 0.17"/>
  </joint>
  <transmission name="left_gear_joint_trans">
    <type>transmission_interface/SimpleTransmission</type>
    <joint name="left_gear_joint">
      <hardwareInterface>hardware_interface/PositionJointInterface</hardwareInterface>
    </joint>
    <actuator name="left_gear_joint_motor">
      <mechanicalReduction>1</mechanicalReduction>
    </actuator>
  </transmission>
  <gazebo>
    <!-- loading plugin: mimic joints works in gazebo now-->
    <plugin filename="libroboticsgroup_gazebo_mimic_joint_plugin.so" name="mimic_joint">
      <joint>left_gear_joint</joint>
      <mimicJoint>right_gear_joint</mimicJoint>
      <multiplier>1.0</multiplier>
    </plugin>
    <plugin filename="libroboticsgroup_gazebo_mimic_joint_plugin.so" name="mimic_joint">
      <joint>left_gear_joint</joint>
      <mimicJoint>right_arm_bottom_joint</mimicJoint>
      <multiplier>-1.0</multiplier>
    </plugin>
    <plugin filename="libroboticsgroup_gazebo_mimic_joint_plugin.so" name="mimic_joint">
      <joint>left_gear_joint</joint>
      <mimicJoint>left_arm_bottom_joint</mimicJoint>
      <multiplier>1.0</multiplier>
    </plugin>
    <plugin filename="libroboticsgroup_gazebo_mimic_joint_plugin.so" name="mimic_joint">
      <joint>left_gear_joint</joint>
      <mimicJoint>right_arm_top_joint</mimicJoint>
      <multiplier>-1.0</multiplier>
    </plugin>
    <plugin filename="libroboticsgroup_gazebo_mimic_joint_plugin.so" name="mimic_joint">
      <joint>left_gear_joint</joint>
      <mimicJoint>left_arm_top_joint</mimicJoint>
      <multiplier>1.0</multiplier>
    </plugin>
    <plugin filename="libroboticsgroup_gazebo_mimic_joint_plugin.so" name="mimic_joint">
      <joint>left_gear_joint</joint>
      <mimicJoint>left_stick_joint</mimicJoint>
      <multiplier>-1.0</multiplier>
    </plugin>
    <plugin filename="libroboticsgroup_gazebo_mimic_joint_plugin.so" name="mimic_joint">
      <joint>left_gear_joint</joint>
      <mimicJoint>right_stick_joint</mimicJoint>
      <multiplier>1.0</multiplier>
    </plugin>
    <plugin filename="libroboticsgroup_gazebo_mimic_joint_plugin.so" name="mimic_joint">
      <joint>left_gear_joint</joint>
      <mimicJoint>left_stick_top_joint</mimicJoint>
      <multiplier>-1.0</multiplier>
    </plugin>
    <plugin filename="libroboticsgroup_gazebo_mimic_joint_plugin.so" name="mimic_joint">
      <joint>left_gear_joint</joint>
      <mimicJoint>right_stick_top_joint</mimicJoint>
      <multiplier>1.0</multiplier>
    </plugin>
  </gazebo>
  <!-- inertia factor -->
  <link name="base_bottom">
    <visual>
      <geometry>
        <mesh filename="package://ur3_sim_description/meshes/gripper/BaseBottom.dae" scale="0.001 0.001 0.001"/>
      </geometry>
    </visual>
    <collision>
      <geometry>
        <mesh filename="package://ur3_sim_description/meshes/gripper/BaseBottom.dae" scale="0.001 0.001 0.001"/>
      </geometry>
    </collision>
    <inertial>
      <mass value="0.00002265"/>
      <origin rpy="0 0 0" xyz="0.022834885 -0.035958401 0.002623114"/>
      <inertia ixx="0.00198528736" ixy="-0.00000264564125000" ixz="-0.00000829723937500" iyx="-0.00000264564125000" iyy="0.00093770280000000" iyz="0.00025834140000000" izx="-0.00000829723937500" izy="0.00025834140000000" izz="0.00252391792000000"/>
    </inertial>
  </link>
  <gazebo reference="base_bottom">
    <material>Gazebo/DarkGrey</material>
    <turnGravityOff>true</turnGravityOff>
  </gazebo>
  <link name="adapter">
    <visual>
      <geometry>
        <mesh filename="package://ur3_sim_description/meshes/gripper/Adapter.dae" scale="0.001 0.001 0.001"/>
      </geometry>
    </visual>
    <collision>
      <geometry>
        <mesh filename="package://ur3_sim_description/meshes/gripper/Adapter.dae" scale="0.001 0.001 0.001"/>
      </geometry>
    </collision>
    <inertial>
      <mass value="0.00002265"/>
      <origin rpy="0 0 0" xyz="0.022834885 -0.035958401 0.002623114"/>
      <inertia ixx="0.00198528736" ixy="-0.00000264564125000" ixz="-0.00000829723937500" iyx="-0.00000264564125000" iyy="0.00093770280000000" iyz="0.00025834140000000" izx="-0.00000829723937500" izy="0.00025834140000000" izz="0.00252391792000000"/>
    </inertial>
  </link>
  <gazebo reference="adapter">
    <material>Gazebo/DarkGrey</material>
    <turnGravityOff>true</turnGravityOff>
  </gazebo>
  <joint name="adapter_joint" type="fixed">
    <parent link="base_bottom"/>
    <child link="adapter"/>
    <origin xyz="0.0 0 0.0"/>
  </joint>
  <link name="left_gear">
    <visual>
      <origin xyz="0.0 0 0.0"/>
      <geometry>
        <mesh filename="package://ur3_sim_description/meshes/gripper/MainGear2.dae" scale="0.001 0.001 0.001"/>
      </geometry>
    </visual>
    <collision>
      <origin xyz="0.0 0 0.0"/>
      <geometry>
        <mesh filename="package://ur3_sim_description/meshes/gripper/MainGear2.dae" scale="0.001 0.001 0.001"/>
      </geometry>
    </collision>
    <inertial>
      <mass value="0.00002265"/>
      <origin rpy="0 0 0" xyz="-0.004189223000000001 -6.5e-08 0.009676432"/>
      <!--  divide by 10E-11     -->
      <inertia ixx="4.8774819999999994e-05" ixy="-3.4191254e-10" ixz="-4.165070312499999e-06" iyx="-3.4191254e-10" iyy="9.591456999999999e-05" iyz="5.05108643e-09" izx="-4.165070312499999e-06" izy="5.05108643e-09" izz="5.05108643e-09"/>
    </inertial>
  </link>
  <gazebo reference="left_gear">
    <material>Gazebo/Grey</material>
    <turnGravityOff>true</turnGravityOff>
  </gazebo>
  <joint name="left_gear_joint" type="revolute">
    <parent link="base_bottom"/>
    <child link="left_gear"/>
    <axis xyz="0 0 -1"/>
    <origin xyz="0.0 0 0.0"/>
    <limit effort="1000.0" lower="-2.0" upper="2.0" velocity="1.5"/>
  </joint>
  <link name="right_gear">
    <visual>
      <origin xyz="-0.044341 0 0.0"/>
      <geometry>
        <mesh filename="package://ur3_sim_description/meshes/gripper/MainGear1.dae" scale="0.001 0.001 0.001"/>
      </geometry>
    </visual>
    <collision>
      <origin xyz="-0.044341 0 0.0"/>
      <geometry>
        <mesh filename="package://ur3_sim_description/meshes/gripper/MainGear1.dae" scale="0.001 0.001 0.001"/>
      </geometry>
    </collision>
    <inertial>
      <mass value="0.00002265"/>
      <origin rpy="0 0 0" xyz="0.048526249 -1.46e-07 0.009676307"/>
      <!--  divide by 10E-11     -->
      <inertia ixx="4.8844599999999996e-05" ixy="8.5138191e-10" ixz="4.1636959375e-06" iyx="8.5138191e-10" iyy="9.598415999999999e-05" iyz="-5.2216833499999995e-09" izx="4.1636959375e-06" izy="4.1636959375e-06" izz="0.00012235934999999998"/>
    </inertial>
  </link>
  <gazebo reference="right_gear">
    <material>Gazebo/Grey</material>
    <turnGravityOff>true</turnGravityOff>
  </gazebo>
  <joint name="right_gear_joint" type="revolute">
    <parent link="base_bottom"/>
    <child link="right_gear"/>
    <axis xyz="0 0 1"/>
    <origin xyz="0.044341 0 0.0"/>
    <limit effort="1000.0" lower="-2.0" upper="2.0" velocity="1.5"/>
    <mimic joint="left_gear_joint" multiplier="1" offset="0"/>
  </joint>
  <link name="right_arm_bottom">
    <visual>
      <origin xyz="-0.094414 0 0.0"/>
      <geometry>
        <mesh filename="package://ur3_sim_description/meshes/gripper/Arm_R_Bottom.dae" scale="0.001 0.001 0.001"/>
      </geometry>
    </visual>
    <collision>
      <origin xyz="-0.094414 0 0.0"/>
      <geometry>
        <mesh filename="package://ur3_sim_description/meshes/gripper/Arm_R_Bottom.dae" scale="0.001 0.001 0.001"/>
      </geometry>
    </collision>
    <inertial>
      <mass value="0.0001"/>
      <inertia ixx="0.001" ixy="0.0" ixz="0.0" iyy="0.001" iyz="0.0" izz="0.001"/>
    </inertial>
  </link>
  <gazebo reference="right_arm_bottom">
    <material>Gazebo/DarkGrey</material>
    <turnGravityOff>true</turnGravityOff>
  </gazebo>
  <joint name="right_arm_bottom_joint" type="revolute">
    <joint_properties damping="1000.0" friction="1000.0"/>
    <parent link="right_gear"/>
    <child link="right_arm_bottom"/>
    <axis xyz="0 0 1"/>
    <origin xyz="0.050137 0 0.0"/>
    <limit effort="1000.0" lower="-2.0" upper="2.0" velocity="1.5"/>
    <mimic joint="left_gear_joint" multiplier="-1" offset="0"/>
  </joint>
  <link name="left_arm_bottom">
    <visual>
      <origin xyz="0.050137 0 0.0"/>
      <geometry>
        <mesh filename="package://ur3_sim_description/meshes/gripper/Arm_L_Bottom.dae" scale="0.001 0.001 0.001"/>
      </geometry>
    </visual>
    <collision>
      <origin xyz="0.050137 0 0.0"/>
      <geometry>
        <mesh filename="package://ur3_sim_description/meshes/gripper/Arm_L_Bottom.dae" scale="0.001 0.001 0.001"/>
      </geometry>
    </collision>
    <inertial>
      <mass value="0.0001"/>
      <inertia ixx="0.001" ixy="0.0" ixz="0.0" iyy="0.001" iyz="0.0" izz="0.001"/>
    </inertial>
  </link>
  <gazebo reference="left_arm_bottom">
    <material>Gazebo/DarkGrey</material>
    <turnGravityOff>true</turnGravityOff>
  </gazebo>
  <joint name="left_arm_bottom_joint" type="revolute">
    <joint_properties damping="1000.0" friction="1000.0"/>
    <parent link="left_gear"/>
    <child link="left_arm_bottom"/>
    <axis xyz="0 0 1"/>
    <origin xyz="-0.050137 0 0.0"/>
    <limit effort="1000.0" lower="-2.0" upper="2.0" velocity="1.5"/>
    <mimic joint="left_gear_joint" multiplier="1" offset="0"/>
  </joint>
  <link name="right_arm_top">
    <visual>
      <origin rpy="0.0 0.0 0.0" xyz="0.060137 0 0.027123"/>
      <geometry>
        <mesh filename="package://ur3_sim_description/meshes/gripper/Arm_R_Top.dae" scale="0.001 0.001 0.001"/>
      </geometry>
    </visual>
    <collision>
      <origin rpy="0.0 0.0 0.0" xyz="0.060137  0 0.027123"/>
      <geometry>
        <mesh filename="package://ur3_sim_description/meshes/gripper/Arm_R_Top.dae" scale="0.001 0.001 0.001"/>
      </geometry>
    </collision>
    <inertial>
      <mass value="0.0001"/>
      <inertia ixx="0.001" ixy="0.0" ixz="0.0" iyy="0.001" iyz="0.0" izz="0.001"/>
    </inertial>
  </link>
  <gazebo reference="right_arm_top">
    <material>Gazebo/DarkGrey</material>
    <turnGravityOff>true</turnGravityOff>
  </gazebo>
  <joint name="right_arm_top_joint" type="revolute">
    <parent link="right_gear"/>
    <child link="right_arm_top"/>
    <axis xyz="0 0 1"/>
    <origin xyz="0.050137  0 0.0"/>
    <limit effort="1000.0" lower="-2.0" upper="2.0" velocity="1.5"/>
    <mimic joint="left_gear_joint" multiplier="-1" offset="0"/>
  </joint>
  <link name="left_arm_top">
    <visual>
      <origin xyz="0.050137 0 0.0"/>
      <geometry>
        <mesh filename="package://ur3_sim_description/meshes/gripper/Arm_L_Top.dae" scale="0.001 0.001 0.001"/>
      </geometry>
    </visual>
    <collision>
      <origin xyz="0.050137 0 0.0"/>
      <geometry>
        <mesh filename="package://ur3_sim_description/meshes/gripper/Arm_L_Top.dae" scale="0.001 0.001 0.001"/>
      </geometry>
    </collision>
    <inertial>
      <mass value="0.0001"/>
      <inertia ixx="0.001" ixy="0.0" ixz="0.0" iyy="0.001" iyz="0.0" izz="0.001"/>
    </inertial>
  </link>
  <gazebo reference="left_arm_top">
    <material>Gazebo/DarkGrey</material>
    <turnGravityOff>true</turnGravityOff>
  </gazebo>
  <joint name="left_arm_top_joint" type="revolute">
    <parent link="left_gear"/>
    <child link="left_arm_top"/>
    <axis xyz="0 0 1"/>
    <origin xyz="-0.050137 0 0.0"/>
    <limit effort="1000.0" lower="-2.0" upper="2.0" velocity="1.5"/>
    <mimic joint="left_gear_joint" multiplier="1" offset="0"/>
  </joint>
  <link name="left_finger">
    <visual>
      <geometry>
        <mesh filename="package://ur3_sim_description/meshes/gripper/Sock1.dae" scale="0.001 0.001 0.001"/>
      </geometry>
    </visual>
    <collision>
      <geometry>
        <mesh filename="package://ur3_sim_description/meshes/gripper/Sock1.dae" scale="0.001 0.001 0.001"/>
      </geometry>
    </collision>
    <inertial>
      <mass value="0.0000002265"/>
      <origin rpy="0 0 0" xyz="-0.025071934 0.06901268 0.008750031"/>
      <!--  divide by 10E-11     -->
      <inertia ixx="5.3334145e-05" ixy="2.1136374999999998e-07" ixz="3.0323486e-10" iyx="2.1136374999999998e-07" iyy="4.08043475e-05" iyz="3.2196716e-10" izx="3.0323486e-10" izy="3.2196716e-10" izz="2.61154725e-05"/>
    </inertial>
  </link>
  <gazebo reference="left_finger">
    <material>Gazebo/DarkYellow</material>
    <gravity>0</gravity>
    <turnGravityOff>true</turnGravityOff>
  </gazebo>
  <joint name="left_finger_joint" type="fixed">
    <parent link="left_arm_bottom"/>
    <child link="left_finger"/>
    <origin xyz="0.050137  0 0.0"/>
  </joint>
  <link name="right_finger">
    <visual>
      <geometry>
        <mesh filename="package://ur3_sim_description/meshes/gripper/Sock2.dae" scale="0.001 0.001 0.001"/>
      </geometry>
    </visual>
    <collision>
      <geometry>
        <mesh filename="package://ur3_sim_description/meshes/gripper/Sock2.dae" scale="0.001 0.001 0.001"/>
      </geometry>
    </collision>
    <inertial>
      <mass value="0.0000002265"/>
      <!--  divide by 10E-11     -->
      <inertia ixx="5.3334145e-05" ixy="2.1136374999999998e-07" ixz="3.0323486e-10" iyx="2.1136374999999998e-07" iyy="4.08043475e-05" iyz="3.2196716e-10" izx="3.0323486e-10" izy="3.2196716e-10" izz="2.61154725e-05"/>
    </inertial>
  </link>
  <gazebo reference="right_finger">
    <material>Gazebo/DarkYellow</material>
    <turnGravityOff>true</turnGravityOff>
  </gazebo>
  <joint name="right_finger_joint" type="fixed">
    <parent link="right_arm_bottom"/>
    <child link="right_finger"/>
    <origin xyz="-0.094414  0 0"/>
  </joint>
  <link name="left_stick">
    <visual>
      <origin xyz="-0.01 -0.033 0.0"/>
      <geometry>
        <mesh filename="package://ur3_sim_description/meshes/gripper/Stick1.dae" scale="0.001 0.001 0.001"/>
      </geometry>
    </visual>
    <collision>
      <origin xyz="-0.01 -0.033 0.0"/>
      <geometry>
        <mesh filename="package://ur3_sim_description/meshes/gripper/Stick1.dae" scale="0.001 0.001 0.001"/>
      </geometry>
    </collision>
    <inertial>
      <mass value="0.00002265"/>
      <origin rpy="0 0 0" xyz="-0.005003726 0.0 0.005024187"/>
      <!--  divide by 10E-11     -->
      <inertia ixx="9.2893898438e-07" ixy="4.8491e-13" ixz="1.07669724e-09" iyx="4.8491e-13" iyy="1.508868875e-05" iyz="-2.6804e-13" izx="1.07669724e-09" izy="-2.6804e-13" izz="1.5085463749999999e-05"/>
    </inertial>
  </link>
  <gazebo reference="left_stick">
    <material>Gazebo/Grey</material>
    <turnGravityOff>true</turnGravityOff>
  </gazebo>
  <joint name="left_stick_joint" type="revolute">
    <parent link="base_bottom"/>
    <child link="left_stick"/>
    <axis xyz="0 0 1"/>
    <origin xyz="0.01 0.033 0.0"/>
    <limit effort="1000.0" lower="-2.0" upper="2.0" velocity="1.5"/>
    <mimic joint="left_gear_joint" multiplier="-1" offset="0"/>
  </joint>
  <link name="right_stick">
    <visual>
      <origin xyz="-0.034341 -0.033 0.0"/>
      <geometry>
        <mesh filename="package://ur3_sim_description/meshes/gripper/Stick2.dae" scale="0.001 0.001 0.001"/>
      </geometry>
    </visual>
    <collision>
      <origin xyz="-0.034341 -0.033 0.0"/>
      <geometry>
        <mesh filename="package://ur3_sim_description/meshes/gripper/Stick2.dae" scale="0.001 0.001 0.001"/>
      </geometry>
    </collision>
    <inertial>
      <mass value="0.00002265"/>
      <origin rpy="0 0 0" xyz="0.059337273 0.033 0.005024188"/>
      <!--  divide by 10E-11     -->
      <inertia ixx="9.289412499999999e-07" ixy="7.831899999999999e-13" ixz="1.07686089e-09" iyx="7.831899999999999e-13" iyy="1.508869375e-05" iyz="6.557200000000001e-13" izx="1.07686089e-09" izy="6.557200000000001e-13" izz="1.508545e-05"/>
    </inertial>
  </link>
  <gazebo reference="right_stick">
    <material>Gazebo/Grey</material>
    <turnGravityOff>true</turnGravityOff>
  </gazebo>
  <joint name="right_stick_joint" type="revolute">
    <parent link="base_bottom"/>
    <child link="right_stick"/>
    <axis xyz="0 0 1"/>
    <origin xyz="0.034341 0.033 0.0"/>
    <limit effort="1000.0" lower="-2.0" upper="2.0" velocity="1.5"/>
    <mimic joint="left_gear_joint" multiplier="1" offset="0"/>
  </joint>
  <link name="spacer">
    <visual>
      <geometry>
        <mesh filename="package://ur3_sim_description/meshes/gripper/Spacer.dae" scale="0.001 0.001 0.001"/>
      </geometry>
    </visual>
    <collision>
      <geometry>
        <mesh filename="package://ur3_sim_description/meshes/gripper/Spacer.dae" scale="0.001 0.001 0.001"/>
      </geometry>
    </collision>
    <inertial>
      <mass value="0.00002265"/>
      <origin rpy="0 0 0" xyz="0.022172432000000002 0.031563816 0.015463399000000001"/>
      <!--  divide by 10E-11     -->
      <inertia ixx="1.8169903124999999e-06" ixy="-1.4737192e-10" ixz="-5.3030239e-10" iyx="-1.4737192e-10" iyy="5.471119375e-06" iyz="5.471119375e-06" izx="5.471119375e-06" izy="5.471119375e-06" izz="6.42384e-06"/>
    </inertial>
  </link>
  <gazebo reference="spacer">
    <material>Gazebo/DarkGrey</material>
    <turnGravityOff>true</turnGravityOff>
  </gazebo>
  <joint name="spacer_joint" type="fixed">
    <parent link="base_bottom"/>
    <child link="spacer"/>
    <!--    <origin xyz="-0.094414  0 0.0"/>-->
  </joint>
  <link name="left_stick_top">
    <visual>
      <origin xyz="-0.01 -0.033 0.0"/>
      <geometry>
        <mesh filename="package://ur3_sim_description/meshes/gripper/Stick_Top1.dae" scale="0.001 0.001 0.001"/>
      </geometry>
    </visual>
    <collision>
      <origin xyz="-0.01 -0.033 0.0"/>
      <geometry>
        <mesh filename="package://ur3_sim_description/meshes/gripper/Stick_Top1.dae" scale="0.001 0.001 0.001"/>
      </geometry>
    </collision>
    <inertial>
      <mass value="0.00002265"/>
      <origin rpy="0 0 0" xyz="-0.005003726 0.0 0.005024187"/>
      <!--  divide by 10E-11     -->
      <inertia ixx="9.2893898438e-07" ixy="4.8491e-13" ixz="1.07669724e-09" iyx="4.8491e-13" iyy="1.508868875e-05" iyz="-2.6804e-13" izx="1.07669724e-09" izy="-2.6804e-13" izz="1.5085463749999999e-05"/>
    </inertial>
  </link>
  <gazebo reference="left_stick_top">
    <material>Gazebo/Grey</material>
    <turnGravityOff>true</turnGravityOff>
  </gazebo>
  <joint name="left_stick_top_joint" type="revolute">
    <parent link="base_bottom"/>
    <child link="left_stick_top"/>
    <axis xyz="0 0 1"/>
    <origin xyz="0.01 0.033 0.0"/>
    <limit effort="1000.0" lower="-2.0" upper="2.0" velocity="1.5"/>
    <mimic joint="left_gear_joint" multiplier="-1" offset="0"/>
  </joint>
  <link name="right_stick_top">
    <visual>
      <origin xyz="-0.034341 -0.033 0.0"/>
      <geometry>
        <mesh filename="package://ur3_sim_description/meshes/gripper/Stick_Top2.dae" scale="0.001 0.001 0.001"/>
      </geometry>
    </visual>
    <collision>
      <origin xyz="-0.034341 -0.033 0.0"/>
      <geometry>
        <mesh filename="package://ur3_sim_description/meshes/gripper/Stick_Top2.dae" scale="0.001 0.001 0.001"/>
      </geometry>
    </collision>
    <inertial>
      <mass value="0.00002265"/>
      <origin rpy="0 0 0" xyz="0.059337273 0.033 0.005024188"/>
      <!--  divide by 10E-11     -->
      <inertia ixx="9.289412499999999e-07" ixy="7.831899999999999e-13" ixz="1.07686089e-09" iyx="7.831899999999999e-13" iyy="1.508869375e-05" iyz="6.557200000000001e-13" izx="1.07686089e-09" izy="6.557200000000001e-13" izz="1.508545e-05"/>
    </inertial>
  </link>
  <gazebo reference="right_stick_top">
    <material>Gazebo/Grey</material>
    <turnGravityOff>true</turnGravityOff>
  </gazebo>
  <joint name="right_stick_top_joint" type="revolute">
    <parent link="base_bottom"/>
    <child link="right_stick_top"/>
    <axis xyz="0 0 1"/>
    <origin xyz="0.034341 0.033 0.0"/>
    <limit effort="1000.0" lower="-2.0" upper="2.0" velocity="1.5"/>
    <mimic joint="left_gear_joint" multiplier="1" offset="0"/>
  </joint>
  <link name="base_top">
    <visual>
      <geometry>
        <mesh filename="package://ur3_sim_description/meshes/gripper/BaseTopCamera.dae" scale="0.001 0.001 0.001"/>
      </geometry>
    </visual>
    <collision>
      <geometry>
        <mesh filename="package://ur3_sim_description/meshes/gripper/BaseTopCamera.dae" scale="0.001 0.001 0.001"/>
      </geometry>
    </collision>
    <inertial>
      <mass value="0.00002265"/>
      <inertia ixx="0.00198528736" ixy="-0.00000264564125000" ixz="-0.00000829723937500" iyx="-0.00000264564125000" iyy="0.00093770280000000" iyz="0.00025834140000000" izx="-0.00000829723937500" izy="0.00025834140000000" izz="0.00252391792000000"/>
    </inertial>
  </link>
  <gazebo reference="base_top">
    <material>Gazebo/DarkGrey</material>
    <turnGravityOff>true</turnGravityOff>
  </gazebo>
  <joint name="base_top_joint" type="fixed">
    <parent link="base_bottom"/>
    <child link="base_top"/>
    <origin rpy="0.0 0.0 3.141592653589793" xyz="0.0 0.0 0.0205"/>
  </joint>
  <joint name="gripper" type="fixed">
    <origin rpy="1.5705 0.0 -1.5705" xyz="0.00875 0.022171 0.0814375"/>
    <parent link="tool0"/>
    <child link="base_bottom"/>
  </joint>
  <link name="cable_block">
    <visual>
      <geometry>
        <mesh filename="package://ur3_sim_description/meshes/gripper/CableBlock.dae" scale="0.001 0.001 0.001"/>
      </geometry>
    </visual>
    <collision>
      <geometry>
        <mesh filename="package://ur3_sim_description/meshes/gripper/CableBlock.dae" scale="0.001 0.001 0.001"/>
      </geometry>
    </collision>
  </link>
  <joint name="cable_block_joint" type="fixed">
    <origin rpy="0.0 0.0 3.141" xyz="0.0 0.0 0.0"/>
    <parent link="base_bottom"/>
    <child link="cable_block"/>
  </joint>
  <link name="camera_mount"/>
  <joint name="camera_mount_joint" type="fixed">
    <origin rpy="1.308996939 0 0" xyz="0.02217 0.00015 0.0739"/>
    <parent link="base_bottom"/>
    <child link="camera_mount"/>
  </joint>
  <link name="camera_pose"/>
  <joint name="camera_pose_joint" type="fixed">
    <origin rpy="-1.5707963267948966 1.5707963267948966 0" xyz="0 0 0"/>
    <parent link="camera_mount"/>
    <child link="camera_pose"/>
  </joint>
  <link name="camera_link"/>
  <joint name="camera_link_joint" type="fixed">
    <parent link="camera_pose"/>
    <child link="camera_link"/>
    <origin rpy="-1.5707963267948966 0 -1.5707963267948966 " xyz="0 0 0"/>
  </joint>
  <gazebo reference="camera_pose">
    <turnGravityOff>true</turnGravityOff>
    <sensor name="camera1" type="camera">
      <update_rate>30</update_rate>
      <camera>
        <horizontal_fov>1.2112585009</horizontal_fov>
        <vertical_fov>0.7417649321</vertical_fov>
        <image>
          <width>640</width>
          <height>480</height>
          <format>RGB8</format>
        </image>
        <clip>
          <near>0.01</near>
          <far>50.0</far>
        </clip>
      </camera>
      <plugin filename="libgazebo_ros_camera.so" name="kinect_controller">
        <baseline>0.2</baseline>
        <alwaysOn>true</alwaysOn>
        <updateRate>30</updateRate>
        <cameraName>camera_image</cameraName>
        <imageTopicName>image_raw</imageTopicName>
        <cameraInfoTopicName>camera_info</cameraInfoTopicName>
        <frameName>camera_link</frameName>
        <distortionK1>0.00000001</distortionK1>
        <distortionK2>0.00000001</distortionK2>
        <distortionK3>0.00000001</distortionK3>
        <distortionT1>0.00000001</distortionT1>
        <distortionT2>0.00000001</distortionT2>
        <CxPrime>0</CxPrime>
        <Cx>0</Cx>
        <Cy>0</Cy>
        <focalLength>0</focalLength>
        <hackBaseline>0</hackBaseline>
      </plugin>
    </sensor>
  </gazebo>
</robot>

